<!-- See LICENSE.md for legal notices. LICENSE.md must be kept together with this file. -->
<mujoco>
    <body name="robot0:hand mount" pos="1 1.2 0.5" euler="2.35619 0 0">
        <inertial mass="0.1" pos="0 0 0" diaginertia="0.001 0.001 0.001"></inertial>
        <body childclass="robot0:asset_class" name="robot0:forearm" pos="0 0.01 0" euler="0 0 0">
            <inertial pos="0.001 -0.002 0.29" quat="0.982 -0.016 0 -0.188" mass="0.4" diaginertia="0.01 0.01 0.0075"></inertial>
            <joint name="robot0:WRJ2" type="slide" pos="0 0 0" axis="0 0 1" range="-0.5 0.5" damping="35"></joint>
            <joint name="robot0:WRJ1" type="slide" pos="0 0 0" axis="1 0 0" range="-0.5 0.5" damping="35" armature="0.005" user="1123"></joint>
            <geom class="robot0:D_Vizual" pos="0 0.01 0.04" name="robot0:V_forearm" mesh="robot0:forearm" euler="0 0 1.57"></geom>
            <geom class="robot0:DC_Hand" name="robot0:C_forearm" type="mesh" mesh="robot0:forearm_cvx" pos="0 0.01 0.04" euler="0 0 1.57" rgba="0.4 0.5 0.6 0.7"></geom>
            <body name="robot0:wrist" pos="0 0 0.256">
                <inertial pos="0.003 0 0.016" quat="0.504 0.496 0.495 0.504" mass="0.3" diaginertia="0.001 0.001 0.001"></inertial>
                <!--joint name="robot0:WRJ1" type="hinge" pos="0 0 0" axis="0 1 -1" range="-1 0.5" damping="20" armature="0.005" user="1123"></joint-->
                <geom class="robot0:D_Vizual" name="robot0:V_wrist" mesh="robot0:wrist"></geom>
                <geom class="robot0:DC_Hand" name="robot0:C_wrist" type="capsule" pos="0 0 0" quat="0.707 0.707 0 0" size="0.015 0.01" rgba="0.4 0.5 0.6 0.1"></geom>
                <body name="robot0:palm" pos="0 0 0.034">
                    <inertial pos="0.006 0 0.036" quat="0.716 0.044 0.075 0.693" mass="0.3" diaginertia="0.001 0.001 0.001"></inertial>
                    <joint name="robot0:WRJ0" type="hinge" pos="0 0 0" axis="1 0 0" range="0 1" damping="1" armature="0.001" user="1122"></joint>
                    <geom class="robot0:D_Vizual" name="robot0:V_palm" mesh="robot0:palm"></geom>
                    <geom class="robot0:DC_Hand" name="robot0:C_palm0" type="box" pos="0.011 0 0.038" size="0.032 0.0111 0.049" rgba="0.4 0.5 0.6 0.1"></geom>
                    <geom class="robot0:DC_Hand" name="robot0:C_palm1" type="box" pos="-0.032 0 0.014" size="0.011 0.0111 0.025" rgba="0.4 0.5 0.6 0.1"></geom>
                    <body name="robot0:ffknuckle" pos="0.033 0 0.095">
                        <inertial pos="0 0 0" quat="0.52 0.854 0.006 -0.003" mass="0.008" diaginertia="1e-05 1e-05 1e-05"></inertial>
                        <geom class="robot0:D_Vizual" name="robot0:V_ffknuckle" mesh="robot0:knuckle"></geom>
                        <body name="robot0:ffproximal" pos="0 0 0">
                            <inertial pos="0 0 0.023" quat="0.707 -0.004 0.004 0.707" mass="0.014" diaginertia="1e-05 1e-05 1e-05"></inertial>
                            <geom class="robot0:D_Vizual" name="robot0:V_ffproximal" mesh="robot0:F3"></geom>
                            <geom class="robot0:DC_Hand" name="robot0:C_ffproximal" type="capsule" pos="0 0 0.0225" size="0.01 0.0225"></geom>
                            <body name="robot0:ffmiddle" pos="0 0 0.045">
                                <inertial pos="0 0 0.011" quat="0.707 0 0 0.707" mass="0.012" diaginertia="1e-05 1e-05 1e-05"></inertial>
                                <geom class="robot0:D_Vizual" name="robot0:V_ffmiddle" mesh="robot0:F2"></geom>
                                <geom class="robot0:DC_Hand" name="robot0:C_ffmiddle" type="capsule" pos="0 0 0.0125" size="0.00805 0.0125"></geom>
                                <body name="robot0:ffdistal" pos="0 0 0.025">
                                    <inertial pos="0 0 0.015" quat="0.707 -0.003 0.003 0.707" mass="0.01" diaginertia="1e-05 1e-05 1e-05"></inertial>
                                    <geom class="robot0:D_Vizual" name="robot0:V_ffdistal"  group="1" pos="0 0 0.001" mesh="robot0:F1"></geom>
                                    <geom class="robot0:DC_Hand" name="robot0:C_ffdistal" group="4" type="capsule" pos="0 0 0.012" size="0.0205 0.012" condim="4"></geom>
                                    <site name="robot0:S_fftip" pos="0 0 0.026" group="4"></site>
                                    <site class="robot0:D_Touch" name="robot0:grip"></site>
                                    <site name="robot0:T_fftip_front_left"  type="box"  group="4"    pos="-0.00451 -0.00451 0.012" size="0.00451 0.00451 0.01905" rgba="1 0 0 0.33"/>
                                    <site name="robot0:T_fftip_front_right" type="box"  group="4"    pos="0.00451 -0.00451 0.012"  size="0.00451 0.00451 0.01905" rgba="0 0 0 0.33"/>
                                    <site name="robot0:T_fftip_back_left"   type="box"  group="4"    pos="-0.00451 0.00451 0.012"  size="0.00451 0.00451 0.01905" rgba="0 0 0 0.33"/>
                                    <site name="robot0:T_fftip_back_right"  type="box"  group="4"    pos="0.00451 0.00451 0.012"   size="0.00451 0.00451 0.01905" rgba="1 0 0 0.33"/>
                                    <site name="robot0:T_fftip_tip"         type="sphere" group="4"  pos="0 0 0.024"               size="0.008"                   rgba="1 1 0 0.33"/>
                                </body>
                            </body>
                        </body>
                    </body>
                    <body name="robot0:mfknuckle" pos="0.011 0 0.099">
                        <inertial pos="0 0 0" quat="0.52 0.854 0.006 -0.003" mass="0.008" diaginertia="1e-05 1e-05 1e-05"></inertial>
                        <geom class="robot0:D_Vizual" name="robot0:V_mfknuckle" mesh="robot0:knuckle"></geom>
                        <body name="robot0:mfproximal" pos="0 0 0" quat="0.707 0.707 0 0">
                            <inertial pos="0 0 0.023" quat="0.707 -0.004 0.004 0.707" mass="0.014" diaginertia="1e-05 1e-05 1e-05"></inertial>
                            <geom class="robot0:D_Vizual" name="robot0:V_mfproximal" mesh="robot0:F3"></geom>
                            <geom class="robot0:DC_Hand" name="robot0:C_mfproximal" type="capsule" pos="0 0 0.0225" size="0.01 0.0225"></geom>
                            <body name="robot0:mfmiddle" pos="0 0 0.045" quat="0.707 0.707 0 0">
                                <inertial pos="0 0 0.012" quat="0.707 0 0 0.707" mass="0.012" diaginertia="1e-05 1e-05 1e-05"></inertial>
                                <geom class="robot0:D_Vizual" name="robot0:V_mfmiddle" mesh="robot0:F2"></geom>
                                <geom class="robot0:DC_Hand" name="robot0:C_mfmiddle" type="capsule" pos="0 0 0.0125" size="0.00805 0.0125"></geom>
                                <body name="robot0:mfdistal" pos="0 0 0.025" quat="0.707 0.707 0 0">
                                    <inertial pos="0 0 0.015" quat="0.707 -0.003 0.003 0.707" mass="0.01" diaginertia="1e-05 1e-05 1e-05"></inertial>
                                    <geom class="robot0:D_Vizual" name="robot0:V_mfdistal" mesh="robot0:F1"></geom>
                                    <geom class="robot0:DC_Hand" name="robot0:C_mfdistal" type="capsule" pos="0 0 0.012" size="0.00705 0.012" condim="4"></geom>
                                </body>
                            </body>
                        </body>
                    </body>
                    <body name="robot0:rfknuckle" pos="-0.011 0 0.095">
                        <inertial pos="0 0 0" quat="0.52 0.854 0.006 -0.003" mass="0.008" diaginertia="1e-05 1e-05 1e-05"></inertial>
                        <geom class="robot0:D_Vizual" name="robot0:V_rfknuckle" mesh="robot0:knuckle"></geom>
                        <body name="robot0:rfproximal" pos="0 0 0" quat="0.707 0.707 0 0">
                            <inertial pos="0 0 0.023" quat="0.707 -0.004 0.004 0.707" mass="0.014" diaginertia="1e-05 1e-05 1e-05"></inertial>
                            <geom class="robot0:D_Vizual" name="robot0:V_rfproximal" mesh="robot0:F3"></geom>
                            <geom class="robot0:DC_Hand" name="robot0:C_rfproximal" type="capsule" pos="0 0 0.0225" size="0.01 0.0225"></geom>
                            <body name="robot0:rfmiddle" pos="0 0 0.045" quat="0.707 0.707 0 0">
                                <inertial pos="0 0 0.012" quat="0.707 0 0 0.707" mass="0.012" diaginertia="1e-05 1e-05 1e-05"></inertial>
                                <geom class="robot0:D_Vizual" name="robot0:V_rfmiddle" mesh="robot0:F2"></geom>
                                <geom class="robot0:DC_Hand" name="robot0:C_rfmiddle" type="capsule" pos="0 0 0.0125" size="0.00805 0.0125"></geom>
                                <body name="robot0:rfdistal" pos="0 0 0.025" quat="0.707 0.707 0 0">
                                    <inertial pos="0 0 0.015" quat="0.707 -0.003 0.003 0.707" mass="0.01" diaginertia="1e-05 1e-05 1e-05"></inertial>
                                    <geom class="robot0:D_Vizual" name="robot0:V_rfdistal" mesh="robot0:F1" pos="0 0 0.001"></geom>
                                    <geom class="robot0:DC_Hand" name="robot0:C_rfdistal" type="capsule" pos="0 0 0.012" size="0.00705 0.012" condim="4"></geom>
                                </body>
                            </body>
                        </body>
                    </body>
                    <body name="robot0:lfmetacarpal" pos="-0.017 0 0.044">
                        <inertial pos="-0.014 0.001 0.014" quat="0.709 -0.092 -0.063 0.696" mass="0.075" diaginertia="1e-05 1e-05 1e-05"></inertial>
                        <geom class="robot0:D_Vizual" name="robot0:V_lfmetacarpal" pos="-0.016 0 -0.023" mesh="robot0:lfmetacarpal"></geom>
                        <geom class="robot0:DC_Hand" name="robot0:C_lfmetacarpal" type="box" pos="-0.0165 0 0.01" size="0.0095 0.0111 0.025" rgba="0.4 0.5 0.6 0.2"></geom>
                        <body name="robot0:lfknuckle" pos="-0.017 0 0.044">
                            <inertial pos="0 0 0" quat="0.52 0.854 0.006 -0.003" mass="0.008" diaginertia="1e-05 1e-05 1e-05"></inertial>
                            <geom class="robot0:D_Vizual" name="robot0:V_lfknuckle" mesh="robot0:knuckle"></geom>
                            <body name="robot0:lfproximal" pos="0 0 0" quat="0.707 0.707 0 0">
                                <inertial pos="0 0 0.023" quat="0.707 -0.004 0.004 0.707" mass="0.014" diaginertia="1e-05 1e-05 1e-05"></inertial>
                                <geom class="robot0:D_Vizual" name="robot0:V_lfproximal" mesh="robot0:F3"></geom>
                                <geom class="robot0:DC_Hand" name="robot0:C_lfproximal" type="capsule" pos="0 0 0.0225" size="0.01 0.0225"></geom>
                                <body name="robot0:lfmiddle" pos="0 0 0.045" quat="0.707 0.707 0 0">
                                    <inertial pos="0 0 0.012" quat="0.707 0 0 0.707" mass="0.012" diaginertia="1e-05 1e-05 1e-05"></inertial>
                                    <geom class="robot0:D_Vizual" name="robot0:V_lfmiddle" mesh="robot0:F2"></geom>
                                    <geom class="robot0:DC_Hand" name="robot0:C_lfmiddle" type="capsule" pos="0 0 0.0125" size="0.00805 0.0125"></geom>
                                    <body name="robot0:lfdistal" pos="0 0 0.025" quat="0.707 0.707 0 0">
                                        <inertial pos="0 0 0.015" quat="0.707 -0.003 0.003 0.707" mass="0.01" diaginertia="1e-05 1e-05 1e-05"></inertial>
                                        <geom class="robot0:D_Vizual" name="robot0:V_lfdistal" mesh="robot0:F1" pos="0 0 0.001"></geom>
                                        <geom class="robot0:DC_Hand" name="robot0:C_lfdistal" type="capsule" pos="0 0 0.012" size="0.00705 0.012" condim="4"></geom>
                                    </body>
                                </body>
                            </body>
                        </body>
                    </body>
                    <body name="robot0:thbase" pos="0.034 -0.009 0.029" axisangle="0 1 0 2.5">
                        <inertial pos="0 0 0" mass="0.01" diaginertia="1e-05 1e-05 1e-05"></inertial>
                        <geom name="robot0:V_thbase" type="box" group="1" pos="0 0 0" size="0.001 0.001 0.001"></geom>
                        <body name="robot0:thproximal" pos="0 0 0" quat="0.607 0.807 0 0">
                            <inertial pos="0 0 0.017" quat="0.982 0 0.001 0.191" mass="0.016" diaginertia="1e-05 1e-05 1e-05"></inertial>
                            <geom class="robot0:D_Vizual" name="robot0:V_thproximal" mesh="robot0:TH3_z"></geom>
                            <geom class="robot0:DC_Hand" name="robot0:C_thproximal" type="capsule" pos="0 0 0.019" size="0.013 0.019" rgba="0.4 0.5 0.6 0.1"></geom>
                            <body name="robot0:thhub" pos="0 0 0.038" quat="0.907 0.507 0 0">
                                <inertial pos="0 0 0" mass="0.002" diaginertia="1e-05 1e-05 1e-05"></inertial>
                                <geom name="robot0:V_thhub" type="box" group="1" pos="0 0 0" size="0.001 0.001 0.001"></geom>
                                <body name="robot0:thmiddle" pos="0 0 0">
                                    <inertial pos="0 0 0.016" quat="1 -0.001 -0.007 0.003" mass="0.016" diaginertia="1e-05 1e-05 1e-05"></inertial>
                                    <geom class="robot0:D_Vizual" name="robot0:V_thmiddle" mesh="robot0:TH2_z"></geom>
                                    <geom class="robot0:DC_Hand" name="robot0:C_thmiddle" type="capsule" pos="0 0 0.016" size="0.011 0.016"></geom>
                                    <body name="robot0:thdistal" pos="0 0 0.032" quat="0.907 0.107 0 0">
                                        <inertial pos="0 0 0.016" quat="0.999 -0.005 -0.047 0.005" mass="0.016" diaginertia="1e-05 1e-05 1e-05"></inertial>
                                        <geom class="robot0:D_Vizual" name="robot0:V_thdistal" mesh="robot0:TH1_z"></geom>
                                        <geom class="robot0:DC_Hand" name="robot0:C_thdistal" type="capsule" pos="0 0 0.013" size="0.00918 0.013" condim="4"></geom>
                                    </body>
                                </body>
                            </body>
                        </body>
                    </body>
                </body>
            </body>
        </body>
    </body>
</mujoco>
