<mujoco model="NuFinger+">
    <compiler angle="radian" meshdir="./" />
    <size njmax="500" nconmax="100" />
    <asset>
        <material name="table_mat" specular="0" shininess="0.5" reflectance="0" rgba="0.93 0.93 0.93 1"></material>
        
        <mesh name="base_link_L" file="base_link_L.STL" />
        <mesh name="Link_1_L" file="Link_1_L.STL" />
        <mesh name="Link_2_L" file="Link_2_L.STL" />
        <mesh name="base_link_R" file="base_link_R.STL" />
        <mesh name="Link_1_R" file="Link_1_R.STL" />
        <mesh name="Link_2_R" file="Link_2_R.STL" />
        <mesh name="Sensor_base" file="Sensor_base.STL" />
        <mesh name="Sensor_middle" file="Sensor_middle.STL" />
    </asset>
    <worldbody>
    
	    <light directional="true" ambient="0.2 0.2 0.2" diffuse="0.8 0.8 0.8" specular="0.3 0.3 0.3" castshadow="false" pos="0 0 4" dir="0 0 -1" name="light0"/>
	    <geom name='ground' size="0.125 0.125 0.00625" pos="0 0 -0.00625" type="box" contype="1" conaffinity="0" material="table_mat"/>
	    <camera name="fixed" pos="0 -0.7 0.7" quat="0.92388 0.382683 0 0" />
	    <!-- Camera for the VIL paper -->
	    <camera name="vil_camera" pos="0 -1.2 1.2" quat="0.92388 0.382683 0 0" />

	    <body name="base_link_L" pos="0.1 -0.05 0">
		    <inertial pos="-0.0127 -0.0381 0.023237" quat="0.706892 0.706891 0.0174838 0.0174101" mass="0.10435" diaginertia="3.5163E-05 3.5888E-05 9.7478E-06" />
		    <geom type="mesh" contype="0" conaffinity="0" group="1" rgba="0.37255 0.38824 0.43922 1" mesh="base_link_L" />
		    <geom type="mesh" rgba="0.37255 0.38824 0.43922 1" mesh="base_link_L" />
		    <body name="Link_1_L" pos="-0.0127 -0.0381 0.043409" quat="0.499998 0.5 -0.5 0.500002">
		        <inertial pos="-0.0018657 0.041762 -9.687e-08" quat="0.706892 0.706891 0.0174838 0.0174101" mass="0.096446" diaginertia="0.000112274 0.00010696 8.04875e-06" />
		        <joint name="Joint_1_L" pos="0 0 0" axis="1 0 0" limited="true" range="-1 1" damping="1e-3"/>
		        <geom type="mesh" contype="0" conaffinity="0" group="1" rgba="0.25098 0.25098 0.25098 1" mesh="Link_1_L" />
		        <geom type="mesh" rgba="0.37255 0.38824 0.43922 1" mesh="Link_1_L" />
		        <body name="Link_2_L" pos="-0.0087376 0.1 0" quat="1.34924e-11 -3.67321e-06 -1 3.67321e-06">
		            <inertial pos="-0.015421 0.018373 0.0010459" quat="0.697669 0.71524 -0.0333357 -0.0240372" mass="0.074035" diaginertia="3.394e-05 2.99498e-05 5.94866e-06" />
		            <joint name="Joint_2_L" pos="0 0 0" axis="1 0 0" limited="true" range="-2 2" damping="1e-2"/>
		            <geom type="mesh" contype="0" conaffinity="0" group="1" rgba="0.25098 0.25098 0.25098 1" mesh="Link_2_L" />
		            <geom type="mesh" rgba="0.37255 0.38824 0.43922 1" mesh="Link_2_L" />
		        </body>
		    </body>
	    </body>

        <body name="base_link_R" pos="0.1 0.1278 0">
		    <inertial pos="-0.0127 -0.0381 0.023237" quat="0.706892 0.706891 0.0174838 0.0174101" mass="0.10435" diaginertia="3.5163E-05 3.5888E-05 9.7478E-06" />
		    <geom type="mesh" contype="0" conaffinity="0" group="1" rgba="0.37255 0.38824 0.43922 1" mesh="base_link_R" />
		    <geom type="mesh" rgba="0.37255 0.38824 0.43922 1" mesh="base_link_R" />
		    <body name="Link_1_R" pos="-0.0127 -0.0381 0.043409" quat="0.499998 0.5 -0.5 0.500002">
                <inertial pos="-0.0018657 0.041762 -9.687e-08" quat="0.706892 0.706891 0.0174838 0.0174101" mass="0.096446" diaginertia="0.000112274 0.00010696 8.04875e-06" />
                <joint name="Joint_1_R" pos="0 0 0" axis="1 0 0" limited="true" range="-1 1" damping="1e-3" />
		        <geom type="mesh" contype="0" conaffinity="0" group="1" rgba="0.25098 0.25098 0.25098 1" mesh="Link_1_R" />
                <geom type="mesh" rgba="0.37255 0.38824 0.43922 1" mesh="Link_1_R" />
                <body name="Link_2_R" pos="-0.0087376 0.1 0" quat="1.34924e-11 -3.67321e-06 -1 3.67321e-06">
                    <inertial pos="-0.015421 0.018359 -0.0010318" quat="0.715245 0.697665 -0.0241332 -0.0332553" mass="0.074035" diaginertia="3.39401e-05 2.99499e-05 5.94834e-06" />
                    <joint name="Joint_2_R" pos="0 0 0" axis="1 0 0" limited="true" range="-2 2" damping="1e-2" />
		            <geom type="mesh" contype="0" conaffinity="0" group="1" rgba="0.25098 0.25098 0.25098 1" mesh="Link_2_R" />
                    <geom type="mesh" rgba="0.37255 0.38824 0.43922 1" mesh="Link_2_R" />
		        </body>
		    </body>
	    </body>
	    
	    <body name="Sensor_base" pos="-0.0524 0 0" quat="-0.5 -0.5 0.5 0.5">
		    <inertial pos="-1.787E-06 0.020969 -0.00023519" mass="0.053699" diaginertia="3.0243E-06 3.6065E-06 5.9611E-06" />
		    <geom type="mesh" contype="0" conaffinity="0" group="1" rgba="0.8 0.93 0.93 1" mesh="Sensor_base" />
            <geom type="mesh" rgba="0.8 0.93 0.93 1" mesh="Sensor_base" />
            <site name="spring_origin_L" size="0.002" type="sphere" pos="0.0216 0.0120 0" rgba="1 1 1 1" group="4"/>
            <site name="spring_origin_R" size="0.002" type="sphere" pos="-0.0216 0.0120 0" rgba="1 1 1 1" group="4"/>
            <body name="Sensor_middle" pos="0 0 0">
                <inertial pos="-4.5754e-06 0.035178 -0.00034553" quat="0.501157 0.498952 0.496494 0.503371" mass="0.083993" diaginertia="3.22103e-05 1.98158e-05 1.86579e-05" />
                <joint name="Sensor_joint" pos="0 0 0" axis="0 -1 0" damping="1e-4"/>
                <site name="spring_end_L" size="0.002" type="sphere" pos="0.03335 0.0120 0" rgba="1 1 1 1" group="4"/>
                <site name="spring_end_R" size="0.002" type="sphere" pos="-0.03335 0.0120 0" rgba="1 1 1 1" group="4"/>
                <geom type="mesh" rgba="0.8 0.93 0.93 1" mesh="Sensor_middle" />
            </body>
        </body>

    </worldbody>
    
    
    <actuator>
        <position name='AJ1_L' kp="1e2" tendon="T1_L" ctrllimited="true" ctrlrange="-10 10" gear="0.0285 0 0 0 0 0"/>
        <position name='AJ2_L' kp="1e2" tendon="T2_L" ctrllimited="true" ctrlrange="-10 10" gear="0.0285 0 0 0 0 0"/>
        <position name='AJ1_R' kp="1e2" tendon="T1_R" ctrllimited="true" ctrlrange="-10 10" gear="0.0285 0 0 0 0 0"/>
        <position name='AJ2_R' kp="1e2" tendon="T2_R" ctrllimited="true" ctrlrange="-10 10" gear="0.0285 0 0 0 0 0"/>
    </actuator>
    
    <equality>
    </equality>
    
    <tendon>
        <spatial name="T0_L" stiffness="1e1" width="0.001" rgba="0.8 0.3 0.1 1">
            <site site="spring_origin_L"/>
            <site site="spring_end_L"/>
        </spatial>
        <spatial name="T0_R" stiffness="1e1" width="0.001" rgba="0.8 0.3 0.1 1">
            <site site="spring_origin_R"/>
            <site site="spring_end_R"/>
        </spatial>
    
        <fixed name="T1_L" stiffness="720">
            <joint joint="Joint_1_L" coef="0.015875"/>
        </fixed>
        <fixed name="T2_L" stiffness="720">
            <joint joint="Joint_1_L" coef="-0.015875"/>
            <joint joint="Joint_2_L" coef="0.015875"/>
        </fixed>
        <fixed name="T1_R" stiffness="720">
            <joint joint="Joint_1_R" coef="0.015875"/>
        </fixed>
        <fixed name="T2_R" stiffness="720">
            <joint joint="Joint_1_R" coef="-0.015875"/>
            <joint joint="Joint_2_R" coef="0.015875"/>
        </fixed>
        
        
        <fixed name="T1_L_2" stiffness="720">
            <joint joint="Joint_1_L" coef="-0.015875"/>
        </fixed>
        <fixed name="T2_L_2" stiffness="720">
            <joint joint="Joint_1_L" coef="0.015875"/>
            <joint joint="Joint_2_L" coef="-0.015875"/>
        </fixed>
        <fixed name="T1_R_2" stiffness="720">
            <joint joint="Joint_1_R" coef="-0.015875"/>
        </fixed>
        <fixed name="T2_R_2" stiffness="720">
            <joint joint="Joint_1_R" coef="0.015875"/>
            <joint joint="Joint_2_R" coef="-0.015875"/>
        </fixed>        
    </tendon>
    
    <contact>
        <exclude body1="Link_1_L" body2="base_link_L"/>
        <exclude body1="Link_1_L" body2="Link_2_L"/>

        <exclude body1="Link_1_R" body2="base_link_R"/>
        <exclude body1="Link_1_R" body2="Link_2_R"/>
        
        <exclude body1="Sensor_base" body2="Sensor_middle"/>
    </contact>
</mujoco>
